


"""
Same example can be written more cleanly as follows âˆ’


"""


try:
   fh = open("testfile", "w")
   try:
      fh.write("This is my test file for exception handling!!")
   finally:
      print ("Going to close the file")
      fh.close()
except IOError:
   print ("Error: can\'t find file or read data")


"""
When an exception is thrown in the try block, the execution immediately passes to the finally block. After all the statements in the finally block are executed, the exception is raised again and is handled in the except statements if present in the next higher layer of the try-except statement

"""

